{"uuid": "11c5e47d-2437-4b22-bd5f-a586422a5dc4", "children": ["6d2bfbd8-7fbf-46b8-a09b-630b11cbe560", "4e2108ff-1809-4af5-91f0-a2d358bed5f0"], "befores": [{"name": "ue_ip", "status": "broken", "statusDetails": {"message": "requests.exceptions.ConnectionError: HTTPConnectionPool(host='172.24.14.11', port=80): Max retries exceeded with url: /mgmt/v1/session/imsi-450051234000000/7 (Caused by NewConnectionError('<urllib3.connection.HTTPConnection object at 0x7f85c05d3710>: Failed to establish a new connection: [Errno 111] Connection refused',))\n", "trace": "  File \"/usr/local/lib/python3.6/dist-packages/pluggy/callers.py\", line 187, in _multicall\n    res = hook_impl.function(*args)\n  File \"/usr/local/lib/python3.6/dist-packages/_pytest/fixtures.py\", line 918, in pytest_fixture_setup\n    result = call_fixture_func(fixturefunc, request, kwargs)\n  File \"/usr/local/lib/python3.6/dist-packages/_pytest/fixtures.py\", line 778, in call_fixture_func\n    res = fixturefunc(**kwargs)\n  File \"/root/overall/test_001_pdu_establishment.py\", line 38, in ue_ip\n    ue_ip = NF.smf_get_session(smf_ip,get_parameter('supi'),get_parameter('pdu_id'))\n  File \"/root/overall/NF.py\", line 32, in smf_get_session\n    rsp = requests.get(url,headers=headers)\n  File \"/usr/lib/python3/dist-packages/requests/api.py\", line 72, in get\n    return request('get', url, params=params, **kwargs)\n  File \"/usr/lib/python3/dist-packages/requests/api.py\", line 58, in request\n    return session.request(method=method, url=url, **kwargs)\n  File \"/usr/lib/python3/dist-packages/requests/sessions.py\", line 520, in request\n    resp = self.send(prep, **send_kwargs)\n  File \"/usr/lib/python3/dist-packages/requests/sessions.py\", line 630, in send\n    r = adapter.send(request, **kwargs)\n  File \"/usr/lib/python3/dist-packages/requests/adapters.py\", line 508, in send\n    raise ConnectionError(e, request=request)\n"}, "start": 1566875337946, "stop": 1566875337954}], "start": 1566875337946, "stop": 1566875352543}